
facebook | update_bio | line 122 | ERROR | 2025-10-14 17:01:24,452 | Failed to update bio: FacebookAPI._try_post() got an unexpected keyword argument 'data'
Traceback (most recent call last):
  File "c:\Users\Rafael\Documents\GitHub\frame-poster\src\facebook.py", line 114, in update_bio
    response = self._try_post(endpoint, data=data)
  File "C:\Users\Rafael\Documents\GitHub\frame-poster\venv\Lib\site-packages\tenacity\__init__.py", line 338, in wrapped_f
    return copy(f, *args, **kw)
  File "C:\Users\Rafael\Documents\GitHub\frame-poster\venv\Lib\site-packages\tenacity\__init__.py", line 477, in __call__
    do = self.iter(retry_state=retry_state)
  File "C:\Users\Rafael\Documents\GitHub\frame-poster\venv\Lib\site-packages\tenacity\__init__.py", line 378, in iter
    result = action(retry_state)
  File "C:\Users\Rafael\Documents\GitHub\frame-poster\venv\Lib\site-packages\tenacity\__init__.py", line 400, in <lambda>
    self._add_action_func(lambda rs: rs.outcome.result())
                                     ~~~~~~~~~~~~~~~~~^^
  File "C:\Users\Rafael\AppData\Local\Programs\Python\Python313\Lib\concurrent\futures\_base.py", line 449, in result
    return self.__get_result()
           ~~~~~~~~~~~~~~~~~^^
  File "C:\Users\Rafael\AppData\Local\Programs\Python\Python313\Lib\concurrent\futures\_base.py", line 401, in __get_result
    raise self._exception
  File "C:\Users\Rafael\Documents\GitHub\frame-poster\venv\Lib\site-packages\tenacity\__init__.py", line 480, in __call__
    result = fn(*args, **kwargs)
TypeError: FacebookAPI._try_post() got an unexpected keyword argument 'data'
facebook | update_bio | line 122 | ERROR | 2025-10-14 17:07:51,878 | Failed to update bio: FacebookAPI._try_post() got an unexpected keyword argument 'data'
Traceback (most recent call last):
  File "C:\Users\Rafael\Documents\GitHub\frame-poster\src\facebook.py", line 114, in update_bio
    response = self._try_post(endpoint, data=data)
  File "c:\Users\Rafael\Documents\GitHub\frame-poster\venv\Lib\site-packages\tenacity\__init__.py", line 338, in wrapped_f
    return copy(f, *args, **kw)
  File "c:\Users\Rafael\Documents\GitHub\frame-poster\venv\Lib\site-packages\tenacity\__init__.py", line 477, in __call__
    do = self.iter(retry_state=retry_state)
  File "c:\Users\Rafael\Documents\GitHub\frame-poster\venv\Lib\site-packages\tenacity\__init__.py", line 378, in iter
    result = action(retry_state)
  File "c:\Users\Rafael\Documents\GitHub\frame-poster\venv\Lib\site-packages\tenacity\__init__.py", line 400, in <lambda>
    self._add_action_func(lambda rs: rs.outcome.result())
                                     ~~~~~~~~~~~~~~~~~^^
  File "C:\Users\Rafael\AppData\Local\Programs\Python\Python313\Lib\concurrent\futures\_base.py", line 449, in result
    return self.__get_result()
           ~~~~~~~~~~~~~~~~~^^
  File "C:\Users\Rafael\AppData\Local\Programs\Python\Python313\Lib\concurrent\futures\_base.py", line 401, in __get_result
    raise self._exception
  File "c:\Users\Rafael\Documents\GitHub\frame-poster\venv\Lib\site-packages\tenacity\__init__.py", line 480, in __call__
    result = fn(*args, **kwargs)
TypeError: FacebookAPI._try_post() got an unexpected keyword argument 'data'
facebook | update_bio | line 122 | ERROR | 2025-10-14 17:09:15,732 | Failed to update bio: FacebookAPI._try_post() got an unexpected keyword argument 'data'
Traceback (most recent call last):
  File "C:\Users\Rafael\Documents\GitHub\frame-poster\src\facebook.py", line 114, in update_bio
    response = self._try_post(endpoint, data=data)
  File "c:\Users\Rafael\Documents\GitHub\frame-poster\venv\Lib\site-packages\tenacity\__init__.py", line 338, in wrapped_f
    return copy(f, *args, **kw)
  File "c:\Users\Rafael\Documents\GitHub\frame-poster\venv\Lib\site-packages\tenacity\__init__.py", line 477, in __call__
    do = self.iter(retry_state=retry_state)
  File "c:\Users\Rafael\Documents\GitHub\frame-poster\venv\Lib\site-packages\tenacity\__init__.py", line 378, in iter
    result = action(retry_state)
  File "c:\Users\Rafael\Documents\GitHub\frame-poster\venv\Lib\site-packages\tenacity\__init__.py", line 400, in <lambda>
    self._add_action_func(lambda rs: rs.outcome.result())
                                     ~~~~~~~~~~~~~~~~~^^
  File "C:\Users\Rafael\AppData\Local\Programs\Python\Python313\Lib\concurrent\futures\_base.py", line 449, in result
    return self.__get_result()
           ~~~~~~~~~~~~~~~~~^^
  File "C:\Users\Rafael\AppData\Local\Programs\Python\Python313\Lib\concurrent\futures\_base.py", line 401, in __get_result
    raise self._exception
  File "c:\Users\Rafael\Documents\GitHub\frame-poster\venv\Lib\site-packages\tenacity\__init__.py", line 480, in __call__
    result = fn(*args, **kwargs)
TypeError: FacebookAPI._try_post() got an unexpected keyword argument 'data'
facebook | update_bio | line 116 | ERROR | 2025-10-14 17:10:32,164 | Failed to update bio: None
facebook | update_bio | line 116 | ERROR | 2025-10-14 17:13:19,461 | Failed to update bio: None
